Workbook
Name \A: '[1]C-27'!#REF!
Name \A: '[1]C-27'!#REF!
Name \A: '[1]C-27'!#REF!
Name \A: '[1]C-27'!#REF!
Name \A: '[1]C-27'!#REF!
Name \A: '[1]C-27'!#REF!
Name \A: '[1]C-27'!#REF!
Name \A: '[1]C-27'!#REF!
Name \A: '[1]C-27'!#REF!
Name \A: '[1]C-27'!#REF!
Name \C: #REF!
Name \C: #REF!
Name \C: #REF!
Name \C: #REF!
Name \C: #REF!
Name \C: #REF!
Name \C: #REF!
Name \C: #REF!
Name \C: #REF!
Name \C: #REF!
Name \e: #REF!
Name \e: #REF!
Name \e: #REF!
Name \e: #REF!
Name \e: #REF!
Name \e: #REF!
Name \e: #REF!
Name \e: #REF!
Name \e: #REF!
Name \e: #REF!
Name \S: #N/A
Name _1990: #REF!
Name _1990: #REF!
Name _1990: #REF!
Name _1990: #REF!
Name _1990: #REF!
Name _1990: #REF!
Name _1990: #REF!
Name _1990: #REF!
Name _1990: #REF!
Name _1990: #REF!
Name A_IMPRESION_IM: '[1]C-27'!$A$1:$Z$22
Name A_IMPRESIÓN_IM: [3]CYPPOLLO!#REF!
Name A_IMPRESIÓN_IM: [3]CYPPOLLO!#REF!
Name A_IMPRESIÓN_IM: [3]CYPPOLLO!#REF!
Name A_IMPRESIÓN_IM: [3]CYPPOLLO!#REF!
Name A_IMPRESIÓN_IM: [3]CYPPOLLO!#REF!
Name A_IMPRESIÓN_IM: [3]CYPPOLLO!#REF!
Name A_IMPRESIÓN_IM: [3]CYPPOLLO!#REF!
Name A_IMPRESIÓN_IM: [3]CYPPOLLO!#REF!
Name A_IMPRESIÓN_IM: [3]CYPPOLLO!#REF!
Name A_IMPRESIÓN_IM: [3]CYPPOLLO!#REF!
Name AGO: #REF!
Name AGO: #REF!
Name AGO: #REF!
Name AGO: #REF!
Name AGO: #REF!
Name AGO: #REF!
Name AGO: #REF!
Name AGO: #REF!

Sheet INDICE
A1: INDICE
A3: Cuadro | B3: Denominación
A4: C.1 | B4: Perú: Valor bruto de la producción agropecuaria por grupos de productos según año, 2015-2016
A5: C.2 | B5: Perú: Valor bruto de la producción agropecuaria por producto según año, 2015-2016
A6: C.3 | B6: Perú: Valor bruto de la producción agrícola y ganadera por departamento según año, 2012-2016
A7: C.4 | B7: Perú: Índice de producción agropecuaria por producto según año, 2005-2016
A8: C.5 | B8: Perú: Superficie cosechada por producto según año, 2012-2016
A9: C.6 | B9: Perú: Producción agrícola por producto según año, 2012-2016
A10: C.7 | B10: Perú: Rendimiento agrícola por producto según año, 2012-2016
A11: C.8 | B11: Perú: Precio recibido por el productor por producto según año, 2011-2015
A12: C.9 | B12: Perú: Superficie sembrada de cereales por región según cultivo, ago 2015-jul 2016
A13: C.10 | B13: Perú: Superficie cosechada de cereales por región según cultivo, año 2016
A14: C.11 | B14: Perú: Producción de cereales por región según producto, año 2016
... A212: C.209 | B212: Perú: Fibra de alpaca por región según variables productivas, 2015/16

Sheet C.1
A1: C.1 PERÚ: VALOR BRUTO DE LA PRODUCCIÓN AGROPECUARIA POR GRUPOS DE PRODUCTOS SEGÚN AÑO, 2015-2016
A2: (millones de soles a precios 2007)
J3: 100
A4: GRUPO | C4: 2015 | D4: 2016 | E4: Var. % 2016/2015 | F4: Aporte p.p. 2016 | G4: Aporte % 2016 | I4: Cultivos de azúcar | J4: 0.022659033
A5: SECTOR AGROPECUARIO | C5: 31645.552 | D5: 32273.455 | E5: 1.984174 | F5: 2.0235435 | G5: 100 | I5: Demás | J5: 0.029288776
A6: PRODUCTOS DE LA AGRICULTURA, HORTICULTURA Y JARDINERÍA COMERCIAL | C6: 19149.606 | D6: 19271.62 | E6: 0.63716455 | F6: 0.38802273 | G6: 59.713535 | I6: Huevos de gallina u otras aves | J6: 0.038379096
B7: Cereales | C7: 4382.8182 | D7: 4154.5471 | E7: -5.2083195 | F7: -0.68376778 | G7: 12.872954 | I7: Leche cruda | J7: 0.050318957
B8: Hortalizas | C8: 2870.5462 | D8: 2851.0871 | E8: -0.67788701 | F8: -0.061073826 | G8: 8.8341553 | I8: Productos de forraje, fibras, plantas vivas, flores y capullos | J8: 0.063129426
B9: Frutas y nueces | C9: 3535.6785 | D9: 3865.7603 | E9: 9.3357418 | F9: 1.1404364 | G9: 11.978142 | I9: Cultivos estimulantes, de especias y aromáticos | J9: 0.064150765
B10: Semillas aceiteras y frutos oleaginosos | C10: 323.84587 | D10: 378.25885 | E10: 16.802124 | F10: 0.20083556 | G10: 1.1720433 | I10: Raíces y tubérculos comestibles | J10: 0.085324425
B11: Raíces y tubérculos comestibles con alto contenido en almidón o inulina | C11: 2877.2127 | D11: 2753.714 | E11: -4.2923038 | F11: -0.37350517 | G11: 8.5324425 | I11: Hortalizas | J11: 0.088341553
B12: Cultivos estimulantes, de especias y aromáticos | C12: 1810.2291 | D12: 2070.3668 | E12: 14.37043 | F12: 0.94016569 | G12: 6.4150765 | I12: Frutas y nueces | J12: 0.11978142
B13: Legumbres (hortalizas leguminosas secas) | C13: 453.41144 | D13: 429.19648 | E13: -5.3406172 | F13: -0.072432742 | G13: 1.3298746 | I13: Cereales | J13: 0.12872954
B14: Cultivos de azúcar | C14: 762.22029 | D14: 731.28526 | E14: -4.0585414 | F14: -0.09378732 | G14: 2.2659033 | I14: Animales vivos | J14: 0.309897
B15: Productos de forraje, fibras, plantas vivas, flores y capullos de flores, tabaco en rama, y caucho natural | C15: 2133.6437 | D15: 2037.4047 | E15: -4.51055 | F15: -0.29039834 | G15: 6.3129426
A16: ANIMALES VIVOS Y PRODUCTOS DE ANIMALES (EXCEPTO LA CARNE) | C16: 12486.123 | D16: 12991.284 | E16: 4.0457758 | F16: 1.6608913 | G16: 40.253775
B17: Animales vivos | C17: 9587.2964 | D17: 10001.447 | E17: 4.3197835 | F17: 1.3652499 | G17: 30.9897
B18: Leche cruda | C18: 1581.5399 | D18: 1623.9666 | E18: 2.6826208 | F18: 0.13766505 | G18: 5.0318957
B19: Huevos de gallina u otras aves, con cáscara, frescos | C19: 1193.1406 | D19: 1238.626 | E19: 3.8122436 | F19: 0.14921351 | G19: 3.8379096
B20: Otros productos de animales | C20: 124.14629 | D20: 127.24425 | E20: 2.4954103 | F20: 0.010033847 | G20: 0.39426907
A21: PRODUCTOS FORESTALES Y DE LA TALA1 | C21: 9.8226261 | D21: 10.55039 | E21: 7.4090514 | F21: 0.0024701222 | G21: 0.032690611
B22: Productos forestales no madereros | C22: 9.8226261 | D22: 10.55039 | E22: 7.4090514 | F22: 0.0024701222 | G22: 0.032690611
A23: 1 Sólo productos de cultivos o crianzas
A24: Fuente: SIEA

Sheet C.2
A1: C.2 PERÚ: VALOR BRUTO DE LA PRODUCCION AGROPECUARIA POR PRODUCTO SEGÚN AÑO, 2015-2016
A2: (millones de soles a precios 2007)
A4: PRODUCTO | C4: 2015 | D4: 2016 | E4: % 2016/ 2015 | F4: Aporte % 2016
A5: SECTOR AGROPECUARIO | C5: 31645.552 | D5: 32273.455 | E5: 1.984174 | F5: 100
A6: PRODUCTOS DE LA AGRICULTURA, HORTICULTURA Y JARDINERÍA COMERCIAL | C6: 19149.606 | D6: 19271.62 | E6: 0.63716455 | F6: 59.713535
A7: Cereales | C7: 4382.8182 | D7: 4154.5471 | E7: -5.2083195 | F7: 12.872954
B8: Trigo | C8: 175.76109 | D8: 156.33984 | E8: -11.0498 | F8: 0.4844224
B9: Maíz amarillo duro | C9: 944.60193 | D9: 809.2185 | E9: -14.332326 | F9: 2.5073811
B10: Maíz amiláceo | C10: 372.09815 | D10: 335.30827 | E10: -9.887145 | F10: 1.03896
B11: Maíz morado | C11: 17.460797 | D11: 17.62297 | E11: 0.92878401 | F11: 0.054605157
B12: Arroz cáscara | C12: 2573.8544 | D12: 2585.5668 | E12: 0.45505216 | F12: 8.0114349
B13: Sorgo grano | C13: 0.099652701 | D13: 0.10628167 | E13: 6.6520696 | F13: 0.00032931606
B14: Cebada grano | C14: 139.47026 | D14: 125.55123 | E14: -9.9799302 | F14: 0.38902321
B15: Avena grano | C15: 12.055126 | D15: 15.79697 | E15: 31.039437 | F15: 0.048947253
B16: Quinua | C16: 129.14434 | D16: 96.882084 | E16: -24.981548 | F16: 0.30019124
B17: Kiwicha | C17: 13.588366 | D17: 7.6370716 | E17: -43.796985 | F17: 0.023663632
B18: Cañihua | C18: 4.6840959 | D18: 4.5170417 | E18: -3.5664138 | F18: 0.013996152
A19: Hortalizas | C19: 2870.5462 | D19: 2851.0871 | E19: -0.67788701 | F19: 8.8341553
B20: Espárrago | C20: 1131.0997 | D20: 1154.0483 | E20: 2.0288789 | F20: 3.5758438
B21: Col | C21: 12.762887 | D21: 12.192344 | E21: -4.4703273 | F21: 0.037778244
B22: Coliflor | C22: 8.243475 | D22: 8.1222337 | E22: -1.4707545 | F22: 0.025166918
B23: Brócoli | C23: 38.634857 | D23: 39.090748 | E23: 1.1799983 | F23: 0.12112353
B24: Lechuga | C24: 24.894018 | D24: 26.684299 | E24: 7.1916099 | F24: 0.08268188
B25: Espinaca | C25: 12.587353 | D25: 11.965374 | E25: -4.9413009 | F25: 0.03707497
B26: Alcachofa | C26: 131.55752 | D26: 159.07045 | E26: 20.913233 | F26: 0.49288325
B27: Acelga | C27: 2.9240456 | D27: 2.6059395 | E27: -10.87897 | F27: 0.0080745603
B28: Sandía | C28: 36.000581 | D28: 32.198389 | E28: -10.561472 | F28: 0.099767409
B29: Melón | C29: 10.81597 | D29: 10.238564 | E29: -5.3384586 | F29: 0.031724414
B30: Ají | C30: 50.245137 | D30: 51.069596 | E30: 1.6408733 | F30: 0.15824025
B31: Rocoto | C31: 22.790193 | D31: 30.123361 | E31: 32.176857 | F31: 0.093337887
... B53: Apio | C53: 13.092735 | D53: 14.320399 | E53: 9.376679 | F53: 0.044372067
A54: Frutas y nueces | C54: 3535.6785 | D54: 3865.7603 | E54: 9.3357418 | F54: 11.978142
B55: Palta | C55: 441.85559 | D55: 534.30059 | E55: 20.921995 | F55: 1.655542
B56: Banano y plátano | C56: 696.53806 | D56: 702.5172 | E56: 0.85840895 | F56: 2.1767648
B57: Dátil | C57: 0.32102804 | D57: 0.36408298 | E57: 13.411581 | F57: 0.001128119
B58: Higo | C58: 2.9642006 | D58: 3.0848463 | E58: 4.0700941 | F58: 0.0095584634
B59: Mango | C59: 187.89283 | D59: 202.84965 | E59: 7.9602897 | F59: 0.62853404
B60: Guayaba | C60: 1.0697312 | D60: 1.0799003 | E60: 0.95062317 | F60: 0.0033460946
B61: Papaya | C61: 41.284969 | D61: 48.332919 | E61: 17.071465 | F61: 0.1497606
B62: Piña | C62: 168.31624 | D62: 172.29451 | E62: 2.363568 | F62: 0.53385828
...

Sheet C.3
A1: C.3 PERÚ: VALOR BRUTO DE LA PRODUCCION AGRÍCOLA Y GANADERA POR DEPARTAMENTO SEGÚN AÑO, 2012-2016
A2: (millones de soles a precios 2007)
A4: Departamento | B4: 2012 | E4: 2013 | H4: 2014 | K4: 2015 | N4: 2016 | Q4: Var. % interanual 2012-2016 | T4: Aporte % 2016
B5: TOTAL | C5: Agrícola | D5: Ganadera | E5: TOTAL | F5: Agrícola | G5: Ganadera | H5: TOTAL | I5: Agrícola | J5: Ganadera | K5: TOTAL | L5: Agrícola | M5: Ganadera | N5: TOTAL | O5: Agrícola | P5: Ganadera | Q5: TOTAL | R5: Agrícola | S5: Ganadera | T5: TOTAL | U5: Agrícola | V5: Ganadera
A6: NACIONAL | B6: 29526.804 | C6: 18460.091 | D6: 11066.714 | E6: 30097.904 | F6: 18638.786 | G6: 11459.118 | H6: 30655.655 | I6: 18790.945 | J6: 11864.71 | K6: 31645.552 | L6: 19159.429 | M6: 12486.123 | N6: 32273.455 | O6: 19282.171 | P6: 12991.284 | Q6: 2.2485723 | R6: 1.0951974 | S6: 4.0898419 | T6: 100 | U6: 59.746225 | V6: 40.253775 | X6: Lima | Y6: 19.886478
A7: Amazonas | B7: 1022.7778 | C7: 875.70065 | D7: 147.07712 | E7: 1049.3388 | F7: 897.38942 | G7: 151.94941 | H7: 1082.7337 | I7: 934.72028 | J7: 148.0134 | K7: 1109.5096 | L7: 958.18259 | M7: 151.32698 | N7: 1066.5506 | O7: 903.62426 | P7: 162.92631 | Q7: 1.0531936 | R7: 0.78782026 | S7: 2.5915342 | T7: 3.3047301 | U7: 2.7998994 | V7: 0.50483071 | X7: La Libertad | Y7: 11.67429
A8: Ancash | B8: 731.91502 | C8: 478.55086 | D8: 253.36416 | E8: 735.50562 | F8: 479.06139 | G8: 256.44422 | H8: 728.28512 | I8: 483.55744 | J8: 244.72768 | K8: 786.05682 | L8: 522.45503 | M8: 263.60179 | N8: 751.56089 | O8: 476.65586 | P8: 274.90503 | Q8: 0.66439291 | R8: -0.09914432 | S8: 2.0608966 | T8: 2.3287277 | U8: 1.4769285 | V8: 0.85179922 | X8: Arequipa | Y8: 8.1182969
A9: Apurímac | B9: 424.02088 | C9: 305.15308 | D9: 118.8678 | E9: 438.33744 | F9: 319.06309 | G9: 119.27435 | H9: 439.43147 | I9: 320.70856 | J9: 118.72291 | K9: 454.58776 | L9: 336.18593 | M9: 118.40183 | N9: 466.40257 | O9: 349.28028 | P9: 117.12229 | Q9: 2.4102496 | R9: 3.4341801 | S9: -0.36914866 | T9: 1.4451585 | U9: 1.0822525 | V9: 0.36290598 | X9: Ica | Y9: 7.635634
A10: Arequipa | B10: 2389.3314 | C10: 1438.7932 | D10: 950.53819 | E10: 2398.3612 | F10: 1400.9925 | G10: 997.36867 | H10: 2517.0092 | I10: 1459.0373 | J10: 1057.9719 | K10: 2495.838 | L10: 1379.8457 | M10: 1115.9924 | N10: 2620.0549 | O10: 1455.7403 | P10: 1164.3145 | Q10: 2.3313016 | R10: 0.29317555 | S10: 5.2022884 | T10: 8.1182969 | U10: 4.510643 | V10: 3.6076539 | X10: San Martín | Y10: 5.9619966
A11: Ayacucho | B11: 588.8748 | C11: 362.73423 | D11: 226.14056 | E11: 584.31333 | F11: 351.61371 | G11: 232.69963 | H11: 569.80134 | I11: 365.92746 | J11: 203.87389 | K11: 577.78961 | L11: 374.38425 | M11: 203.40536 | N11: 562.37662 | O11: 354.58521 | P11: 207.79141 | Q11: -1.1444462 | R11: -0.56643295 | S11: -2.0933299 | T11: 1.7425362 | U11: 1.09869 | V11: 0.6438462 | X11: Piura | Y11: 4.8120743
A12: Cajamarca | B12: 1637.7345 | C12: 1065.8998 | D12: 571.83471 | E12: 1636.3474 | F12: 1039.4192 | G12: 596.9282 | H12: 1613.9942 | I12: 998.77047 | J12: 615.22373 | K12: 1599.7447 | L12: 967.4673 | M12: 632.27738 | N12: 1536.2329 | O12: 936.56721 | P12: 599.66566 | Q12: -1.5867923 | R12: -3.1821039 | S12: 1.1951425 | T12: 4.7600509 | U12: 2.9019738 | V12: 1.8580771 | X12: Cajamarca | Y12: 4.7600509
A13: Cusco | B13: 1077.718 | C13: 763.12553 | D13: 314.5925 | E13: 1074.0191 | F13: 783.38142 | G13: 290.63768 | H13: 1006.3575 | I13: 704.06186 | J13: 302.29559 | K13: 983.68895 | L13: 663.57334 | M13: 320.11561 | N13: 1028.4371 | O13: 706.54866 | P13: 321.88849 | Q13: -1.1633193 | R13: -1.9073373 | S13: 0.57482138 | T13: 3.1866348 | U13: 2.1892564 | V13: 0.99737847 | X13: Junín | Y13: 4.7123646
A14: Huancavelica | B14: 385.76746 | C14: 277.99173 | D14: 107.77573 | E14: 382.82379 | F14: 271.39642 | G14: 111.42737 | H14: 365.18411 | I14: 251.9646 | J14: 113.2195 | K14: 365.19451 | L14: 252.14898 | M14: 113.04553 | N14: 371.4753 | O14: 264.30908 | P14: 107.16623 | Q14: -0.93936911 | R14: -1.2538773 | S14: -0.14168328 | T14: 1.1510243 | U14: 0.81896742 | V14: 0.33205688 | X14: Lambayeque | Y14: 3.3504191
A15: Huánuco | B15: 905.13202 | C15: 668.96091 | D15: 236.17111 | E15: 974.08697 | F15: 716.70146 | G15: 257.38551 | H15: 1009.8303 | I15: 752.04291 | J15: 257.78741 | K15: 1049.381 | L15: 779.21653 | M15: 270.16444 | N15: 992.48066 | O15: 715.02261 | P15: 277.45805 | Q15: 2.3298955 | R15: 1.678647 | S15: 4.1100458 | T15: 3.0752229 | U15: 2.2155131 | V15: 0.85970979 | X15: Amazonas | Y15: 3.3047301
A16: Ica | B16: 2121.3915 | C16: 1521.72 | D16: 599.67151 | E16: 2179.5709 | F16: 1513.7239 | G16: 665.84702 | H16: 2347.4663 | I16: 1567.4229 | J16: 780.04344 | K16: 2388.3147 | L16: 1569.101 | M16: 819.21372 | N16: 2464.2829 | O16: 1569.266 | P16: 895.01682 | Q16: 3.8167506 | R16: 0.77213408 | S16: 10.529815 | T16: 7.635634 | U16: 4.8624049 | V16: 2.7732291 | X16: Cusco | Y16: 3.1866348
A17: Junín | B17: 1481.0743 | C17: 1286.3586 | D17: 194.71579 | E17: 1425.6428 | F17: 1216.7169 | G17: 208.9259 | H17: 1332.143 | I17: 1118.0714 | J17: 214.07164 | K17: 1446.5992 | L17: 1205.5181 | M17: 241.08103 | N17: 1520.8428 | O17: 1241.9335 | P17: 278.90933 | Q17: 0.66462241 | R17: -0.87480016 | S17: 9.3995325 | T17: 4.7123646 | U17: 3.8481579 | V17: 0.86420662 | X17: Huánuco | Y17: 3.0752229
... A23: Moquegua | B23: 135.17379 | C23: 103.05954 | D23: 32.114252 | E23: 149.77082 | F23: 114.06573 | G23: 35.70509 | H23: 133.20001 | I23: 98.399202 | J23: 34.800808 | K23: 139.08812 | L23: 104.70737 | M23: 34.38075 | N23: 123.85768 | O23: 90.152521 | P23: 33.705159 | Q23: -2.1619894 | R23: -3.2897685 | S23: 1.2161096 | T23: 0.38377571 | U23: 0.27933955 | V23: 0.10443617 | X23: Demás | Y23: 7.7931272
A24: Pasco | B24: 327.80707 | C24: 226.20081 | D24: 101.60626 | E24: 349.9543 | F24: 247.31815 | G24: 102.63615 | H24: 347.66004 | I24: 253.79586 | J24: 93.864189 | K24: 382.36211 | L24: 286.55627 | M24: 95.805844 | N24: 391.27713 | O24: 301.807 | P24: 89.470135 | Q24: 4.524124 | R24: 7.4753296 | S24: -3.1299763 | T24: 1.2123807 | U24: 0.93515554 | V24: 0.27722516
A25: Piura | B25: 1414.8883 | C25: 1119.1979 | D25: 295.69035 | E25: 1618.0022 | F25: 1311.0906 | G25: 306.91163 | H25: 1400.3264 | I25: 1104.032 | J25: 296.29438 | K25: 1591.4421 | L25: 1266.6098 | M25: 324.83231 | N25: 1794.3678 | O25: 1483.7388 | P25: 310.62895 | Q25: 6.1200213 | R25: 7.3031919 | S25: 1.2397807 | T25: 5.5598876 | U25: 4.597397 | V25: 0.96249056
A26: Puno | B26: 1298.7521 | C26: 708.03267 | D26: 590.71947 | E26: 1353.612 | F26: 757.23376 | G26: 596.37824 | H26: 1411.6882 | I26: 804.79782 | J26: 606.89039 | K26: 1470.1454 | L26: 897.41037 | M26: 572.73498 | N26: 1463.4932 | O26: 874.04857 | P26: 589.44464 | Q26: 3.0305715 | R26: 5.4072705 | S26: -0.05399616 | T26: 4.5346655 | U26: 2.7082585 | V26: 1.826407
A27: San Martín | B27: 1780.2376 | C27: 1526.9611 | D27: 253.27652 | E27: 1698.3308 | F27: 1442.3892 | G27: 255.94165 | H27: 1845.1679 | I27: 1574.3913 | J27: 270.77661 | K27: 2009.6326 | L27: 1723.1273 | M27: 286.50527 | N27: 2057.3773 | O27: 1758.5819 | P27: 298.7954 | Q27: 3.6833442 | R27: 3.5937755 | S27: 4.2184819 | T27: 6.3748284 | U27: 5.4490043 | V27: 0.92582404
A28: Tacna | B28: 374.58076 | C28: 271.88098 | D28: 102.69978 | E28: 387.36532 | F28: 256.08625 | G28: 131.27907 | H28: 538.98621 | I28: 403.75766 | J28: 135.22856 | K28: 390.72037 | L28: 214.55208 | M28: 176.16829 | N28: 366.16933 | O28: 200.60901 | P28: 165.56031 | Q28: -0.56618037 | R28: -7.3185326 | S28: 12.67996 | T28: 1.1345836 | U28: 0.62159138 | V28: 0.51299223
A29: Tumbes | B29: 173.58482 | C29: 155.3668 | D29: 18.218015 | E29: 157.54961 | F29: 138.329 | G29: 19.220611 | H29: 197.44098 | I29: 177.77867 | J29: 19.662314 | K29: 178.71907 | L29: 159.1971 | M29: 19.521965 | N29: 174.44571 | O29: 163.74047 | P29: 10.705243 | Q29: 0.12375684 | R29: 1.3209951 | S29: -12.446427 | T29: 0.54052382 | U29: 0.50735339 | V29: 0.033170429
A30: Ucayali | B30: 389.69378 | C30: 288.63429 | D30: 101.05949 | E30: 403.84319 | F30: 287.17553 | G30: 116.66767 | H30: 438.81625 | I30: 326.02391 | J30: 112.79235 | K30: 483.26259 | L30: 361.33994 | M30: 121.92266 | N30: 448.9337 | O30: 361.72198 | P30: 87.211725 | Q30: 3.6011759 | R30: 5.8051343 | S30: -3.6172203 | T30: 1.3910308 | U30: 1.1208034 | V30: 0.27022743
A31: Nota: La producción ganadera se refiere a la de animales vivos y productos de animales (excepto la carne)
A32: 1 Incluye El Callao
A33: Fuente: SIEA

Sheet C.4
A1: C.4 PERÚ: INDICE DE PRODUCCIÓN AGROPECUARIA POR PRODUCTO SEGÚN AÑO, 2005-2016
A2: (2009 = 100)
A4: Producto | C4: 2007 | D4: 2008 | E4: 2009 | F4: 2010 | G4: 2011 | H4: 2012 | I4: 2013 | J4: 2014 | K4: 2015 | L4: 2016 | N4: Producto | O4: 2007 | P4: 2008 | Q4: 2009 | R4: 2010 | S4: 2011 | T4: 2012 | U4: 2013 | V4: 2014 | W4: 2015 | X4: 2016
A5: SECTOR AGROPECUARIO | C5: 87.35946 | D5: 99.842424 | E5: 100 | F5: 104.46823 | G5: 115.6013 | H5: 115.18424 | I5: 116.36077 | J5: 123.87933 | K5: 129.75228 | L5: 136.73687 | N5: Cereales | O5: 101.86408 | P5: 129.73398 | Q5: 100 | R5: 108.1585 | S5: 137.77409 | T5: 123.51967 | U5: 125.41051 | V5: 141.86856 | W5: 141.44457 | X5: 148.81488
A6: PRODUCTOS DE LA AGRICULTURA, HORTICULTURA Y JARDINERÍA COMERCIAL | C6: 88.887519 | D6: 103.23333 | E6: 100 | F6: 105.80866 | G6: 121.88032 | H6: 118.47738 | I6: 117.66145 | J6: 126.27662 | K6: 135.1974 | L6: 144.36122 | N6: Hortalizas | O6: 90.834783 | P6: 82.816392 | Q6: 100 | R6: 104.92115 | S6: 101.92945 | T6: 111.96623 | U6: 109.52716 | V6: 122.03756 | W6: 133.03984 | X6: 135.86055
A7: Cereales | C7: 101.86408 | D7: 129.73398 | E7: 100 | F7: 108.1585 | G7: 137.77409 | H7: 123.51967 | I7: 125.41051 | J7: 141.86856 | K7: 141.44457 | L7: 148.81488 | N7: Frutas y nueces | O7: 79.626833 | P7: 94.007098 | Q7: 100 | R7: 95.443108 | S7: 104.45324 | T7: 117.68086 | U7: 115.23476 | V7: 123.91222 | W7: 129.26187 | X7: 170.7727
B8: Trigo | C8: 79.580986 | D8: 103.52705 | E8: 100 | F8: 102.3472 | G8: 104.95052 | H8: 110.61082 | I8: 115.98034 | J8: 119.62769 | K8: 126.60053 | L8: 124.03242 | N8: Semillas aceiteras y frutos oleaginosos | O8: 102.24306 | P8: 93.22428 | Q8: 100 | R8: 100.58867 | S8: 128.08838 | T8: 135.18458 | U8: 123.14024 | V8: 104.02363 | W8: 132.05357 | X8: 187.46879
B9: Maíz amarillo duro | C9: 96.344759 | D9: 108.56065 | E9: 100 | F9: 110.33233 | G9: 133.65175 | H9: 122.60063 | I9: 128.92104 | J9: 132.57302 | K9: 131.89526 | L9: 144.94017 | N9: Raíces y tubérculos comestibles | O9: 73.136785 | P9: 101.5584 | Q9: 100 | R9: 100.15402 | S9: 108.85282 | T9: 116.28906 | U9: 124.95861 | V9: 110.90134 | W9: 143.06296 | X9: 108.78124
B10: Maíz amiláceo | C10: 69.282548 | D10: 89.222573 | E10: 100 | F10: 96.15363 | G10: 107.36888 | H10: 114.37077 | I10: 126.79414 | J10: 118.12225 | K10: 107.51812 | L10: 114.98257 | N10: Cultivos estimulantes, de especias y aromáticos | O10: 100.56985 | P10: 102.04701 | Q10: 100 | R10: 122.27447 | S10: 162.39578 | T10: 121.7004 | U10: 99.784373 | V10: 131.37582 | W10: 125.45578 | X10: 99.548125
B11: Arroz cáscara | C11: 118.02052 | D11: 155.67001 | E11: 100 | F11: 111.12252 | G11: 153.72355 | H11: 127.93622 | I11: 124.58424 | J11: 155.83306 | K11: 157.38471 | L11: 163.69234 | N11: Legumbres (hortalizas leguminosas secas) | O11: 76.682062 | P11: 91.761415 | Q11: 100 | R11: 104.12165 | S11: 108.75508 | T11: 124.35604 | U11: 129.15972 | V11: 128.4199 | W11: 130.50405 | X11: 144.15854
B12: Cebada grano | C12: 71.959343 | D12: 98.170929 | E12: 100 | F12: 105.03318 | G12: 111.04867 | H12: 121.69709 | I12: 125.58556 | J12: 129.98603 | K12: 126.97585 | L12: 130.61436 | N12: Productos de forraje, fibras, plantas vivas, flores | O12: 95.948023 | P12: 104.07568 | Q12: 100 | R12: 118.29328 | S12: 142.15166 | T12: 116.07798 | U12: 117.36596 | V12: 130.7545 | W12: 131.00678 | X12: 164.78172
A13: Hortalizas | C13: 90.834783 | D13: 82.816392 | E13: 100 | F13: 104.92115 | G13: 101.92945 | H13: 111.96623 | I13: 109.52716 | J13: 122.03756 | K13: 133.03984 | L13: 135.86055 | N13: Animales vivos | O13: 84.634261 | P13: 93.429167 | Q13: 100 | R13: 103.5609 | S13: 106.90157 | T13: 110.46126 | U13: 113.91486 | V13: 118.90634 | W13: 120.05425 | X13: 123.6318
B14: Espárrago | C14: 149.61875 | D14: 92.537048 | E14: 100 | F14: 122.53426 | G14: 123.21705 | H14: 134.08101 | I14: 147.48144 | J14: 130.73872 | K14: 178.65836 | L14: 200.67309 | N14: Leche cruda | O14: 88.140901 | P14: 94.873926 | Q14: 100 | R14: 101.10651 | S14: 104.0139 | T14: 109.87855 | U14: 116.99294 | V14: 121.57188 | W14: 124.78896 | X14: 129.80889
B15: Alcachofa | C15: 96.739261 | D15: 94.447355 | E15: 100 | F15: 102.63829 | G15: 102.84124 | H15: 106.53682 | I15: 112.36283 | J15: 141.41754 | K15: 119.1619 | L15: 154.03643 | N15: Huevos de gallina u otras aves, con cáscara, frescos | O15: 79.38518 | P15: 97.832737 | Q15: 100 | R15: 95.880767 | S15: 99.45712 | T15: 106.48786 | U15: 111.0063 | V15: 124.42107 | W15: 122.2818 | X15: 123.57293
B16: Sandía | C16: 93.530049 | D16: 107.6013 | E16: 100 | F16: 111.91017 | G16: 128.71771 | H16: 139.84757 | I16: 134.35404 | J16: 184.77147 | K16: 161.65883 | L16: 155.04901 | N16: Otros productos de animales | O16: 119.02195 | P16: 134.49404 | Q16: 100 | R16: 108.9908 | S16: 126.75076 | T16: 122.53241 | U16: 137.40601 | V16: 139.20085 | W16: 140.65096 | X16: 147.14931
B17: Ají | C17: 128.32968 | D17: 131.60354 | E17: 100 | F17: 191.81214 | G17: 135.16554 | H17: 125.67854 | I17: 130.46352 | J17: 131.11696 | K17: 132.81984 | L17: 151.28634
B18: Piquillo | C18: 93.936815 | D18: 94.339566 | E18: 100 | F18: 123.01645 | G18: 106.78855 | H18: 94.122464 | I18: 63.628756 | J18: 118.59777 | K18: 105.61197 | L18: 69.299541
B19: Tomate | C19: 90.524326 | D19: 115.81467 | E19: 100 | F19: 99.965086 | G19: 100.34497 | H19: 104.43359 | I19: 93.372522 | J19: 119.53197 | K19: 110.0288 | L19: 113.98982
B20: Zapallo | C20: 94.815015 | D20: 114.77708 | E20: 100 | F20: 106.6144 | G20: 134.47792 | H20: 122.95745 | I20: 115.9818 | J20: 161.7489 | K20: 158.83137 | L20: 151.92754
B21: Arveja grano verde | C21: 79.52143 | D21: 100.81566 | E21: 100 | F21: 110.42459 | G21: 119.99945 | H21: 127.19294 | I21: 132.19495 | J21: 145.85669 | K21: 149.95038 | L21: 151.2818
B22: Haba grano verde | C22: 76.249781 | D22: 97.42198 | E22: 100 | F22: 110.35895 | G22: 116.01996 | H22: 130.7628 | I22: 127.28942 | J22: 135.39189 | K22: 135.82321 | L22: 165.73787
B23: Zanahoría | C23: 75.77329 | D23: 97.949703 | E23: 100 | F23: 106.13916 | G23: 129.25088 | H23: 138.09707 | I23: 121.27079 | J23: 127.02528 | K23: 140.87761 | L23: 163.44874
B24: Ajo | C24: 38.199717 | D24: 45.899793 | E24: 100 | F24: 149.41239 | G24: 83.172343 | H24: 55.662335 | I24: 112.60615 | J24: 99.790217 | K24: 93.198955 | L24: 122.25134
B25: Cebolla | C25: 58.956495 | D25: 60.401056 | E25: 100 | F25: 55.641381 | G25: 64.181027 | H25: 99.820148 | I25: 53.70027 | J25: 94.481137 | K25: 102.21074 | L25: 60.55488
B26: Maíz choclo | C26: 78.133896 | D26: 88.312014 | E26: 100 | F26: 103.78849 | G26: 121.39095 | H26: 137.58705 | I26: 136.87938 | J26: 143.54317 | K26: 148.87422 | L26: 154.53981
A27: Frutas y nueces | C27: 79.626833 | D27: 94.007098 | E27: 100 | F27: 95.443108 | G27: 104.45324 | H27: 117.68086 | I27: 115.23476 | J27: 123.91222 | K27: 129.26187 | L27: 170.7727
B28: Palta | C28: 76.851967 | D28: 97.913206 | E28: 100 | F28: 108.42982 | G28: 115.12969 | H28: 132.03777 | I28: 121.3313 | J28: 128.68841 | K28: 147.09308 | L28: 177.45852
B29: Banano y plátano | C29: 81.05662 | D29: 92.161448 | E29: 100 | F29: 95.650809 | G29: 106.60432 | H29: 116.52632 | I29: 118.17256 | J29: 116.74278 | K29: 124.88794 | L29: 173.76049
B30: Mango | C30: 70.638032 | D30: 74.443247 | E30: 100 | F30: 71.857334 | G30: 87.08473 | H30: 96.694332 | I30: 57.998698 | J30: 117.33661 | K30: 111.92991 | L30: 141.10202
B31: Papaya | C31: 70.817846 | D31: 90.983145 | E31: 100 | F31: 93.441336 | G31: 172.20755 | H31: 195.87749 | I31: 137.88567 | J31: 161.03663 | K31: 179.82921 | L31: 159.0812
B32: Piña | C32: 75.832537 | D32: 92.727914 | E32: 100 | F32: 88.18672 | G32: 89.76059 | H32: 107.68211 | I32: 116.52284 | J32: 125.937 | K32: 135.75642 | L32: 172.51447
B33: Maracuyá | C33: 70.15065 | D33: 76.072218 | E33: 100 | F33: 85.287087 | G33: 71.545386 | H33: 84.885089 | I33: 119.09902 | J33: 140.52189 | K33: 102.01488 | L33: 121.22521
B34: Granadilla | C34: 88.650367 | D34: 108.98247 | E34: 100 | F34: 113.98209 | G34: 133.22029 | H34: 135.10381 | I34: 130.92848 | J34: 124.07951 | K34: 107.74145 | L34: 113.06039
B35: Limón | C35: 87.277071 | D35: 137.4704 | E35: 100 | F35: 120.45087 | G35: 156.19943 | H35: 195.94944 | I35: 203.5653 | J35: 183.5128 | K35: 188.15817 | L35: 163.45443
B36: Naranja | C36: 83.886046 | D36: 97.227697 | E36: 100 | F36: 101.4585 | G36: 106.90377 | H36: 114.22677 | I36: 108.51572 | J36: 111.93307 | K36: 121.68717 | L36: 134.90638
B37: Mandarina | C37: 78.876914 | D37: 85.989615 | E37: 100 | F37: 87.670324 | G37: 97.253617 | H37: 106.60478 | I37: 112.15171 | J37: 135.16013 | K37: 120.96 | L37: 147.14426
B38: Tangelo | C38: 88.945091 | D38: 95.149784 | E38: 100 | F38: 105.19422 | G38: 109.88236 | H38: 112.76487 | I38: 110.34413 | J38: 112.92832 | K38: 119.90966 | L38: 158.94531
B39: Uva | C39: 78.558666 | D39: 96.832862 | E39: 100 | F39: 96.7164 | G39: 91.979767 | H39: 105.24518 | I39: 118.52836 | J39: 119.53298 | K39: 130.53713 | L39: 126.00063
... B43: Higo chumbo (tuna) | C43: 88.048798 | D43: 92.790828 | E43: 100 | F43: 95.95219 | G43: 107.72868 | H43: 137.1715 | I43: 156.59216 | J43: 148.30361 | K43: 159.98709 | L43: 93.989997
A44: Semillas aceiteras y frutos oleaginosos | C44: 102.24306 | D44: 93.22428 | E44: 100 | F44: 100.58867 | G44: 128.08838 | H44: 135.18458 | I44: 123.14024 | J44: 104.02363 | K44: 132.05357 | L44: 187.46879
...

Sheet C.5
A1: C.5 PERÚ: SUPERFICIE COSECHADA POR PRODUCTO SEGÚN AÑO, 2012-2016
A2: (Miles hectáreas)
A4: Producto | C4: 2012 | D4: 2013 | E4: 2014 | F4: 2015 | G4: 2016 | H4: Var. % 2012-2016 | I4: % 2016/ 2015
A5: PRODUCTOS DE LA AGRICULTURA, HORTICULTURA Y JARDINERÍA COMERCIAL | C5: 4055.1541 | D5: 4124.9314 | E5: 4071.2732 | F5: 4194.7369 | G5: 4132.45 | H5: 0.4731598 | I5: -1.4848827
A6: Cereales | C6: 1262.7367 | D6: 1281.0569 | E6: 1248.5909 | F6: 1292.0752 | G6: 1239.0717 | H6: -0.47185499 | I6: -4.1021968 | K6: Semillas aceiteras y frutos oleaginosos | L6: 76.53346
B7: Trigo | C7: 151.95237 | D7: 153.64665 | E7: 140.7365 | F7: 138.35713 | G7: 127.17975 | H7: -4.3516191 | I7: -8.078644 | K7: Cultivos de azúcar | L7: 121.90502
B8: Maíz amarillo duro | C8: 294.8432 | D8: 293.71825 | E8: 271.0849 | F8: 297.58817 | G8: 267.5755 | H8: -2.396856 | I8: -10.085303 | K8: Legumbres | L8: 216.23157
B9: Maíz amiláceo | C9: 209.27329 | D9: 216.83233 | E9: 212.9617 | F9: 216.24556 | G9: 197.31152 | H9: -1.4606574 | I9: -8.7558052 | K9: Hortalizas | L9: 231.57546
B10: Maíz morado | C10: 3.73516 | D10: 3.5434 | E10: 3.183 | F10: 3.772 | G10: 3.88265 | H10: 0.9728834 | I10: 2.9334571 | K10: Frutas y nueces | L10: 441.35027
B11: Arroz | C11: 393.89029 | D11: 395.03028 | E11: 381.36792 | F11: 399.501 | G11: 419.56325 | H11: 1.5910716 | I11: 5.0218272 | K11: Raíces y tubérculos comestibles | L11: 485.51664
B12: Sorgo grano | C12: 0.035 | D12: 0.039 | E12: 0.095 | F12: 0.039 | G12: 0.044 | H12: 5.8878568 | I12: 12.820513 | K12: Cultivos estimulantes, de especias y aromáticos | L12: 517.44636
B13: Cebada grano | C13: 151.2135 | D13: 154.12658 | E13: 150.82625 | F13: 145.8369 | G13: 135.74388 | H13: -2.661999 | I13: -6.9207581 | K13: Productos de forraje, fibras, plantas vivas, flores | L13: 802.8195
B14: Avena grano | C14: 11.18275 | D14: 11.3435 | E14: 12.442 | F14: 12.998 | G14: 15.7932 | H14: 9.0135242 | I14: 21.504847 | K14: Cereales | L14: 1239.0717
B15: Quinua | C15: 38.49817 | D15: 44.86787 | E15: 68.14035 | F15: 69.302949 | G15: 64.22319 | H15: 13.648301 | I15: -7.3297877
B16: Kiwicha | C16: 1.718 | D16: 1.633 | E16: 1.35925 | F16: 2.2895 | G16: 1.5998 | H16: -1.7662704 | I16: -30.124481
B17: Cañihua | C17: 6.395 | D17: 6.276 | E17: 6.394 | F17: 6.145 | G17: 6.155 | H17: -0.95173395 | I17: 0.16273393
A18: Hortalizas | C18: 227.43506 | D18: 234.40398 | E18: 230.20416 | F18: 236.70658 | G18: 231.57546 | H18: 0.45204452 | I18: -2.1677141
B19: Espárrago | C19: 33.063 | D19: 33.673 | E19: 31.91915 | F19: 33.86955 | G19: 31.967 | H19: -0.83922646 | I19: -5.6172875
B20: Col | C20: 2.89248 | D20: 2.8027 | E20: 2.740834 | F20: 2.71595 | G20: 2.54612 | H20: -3.1382913 | I20: -6.2530606
B21: Coliflor | C21: 1.3452 | D21: 1.58306 | E21: 1.356 | F21: 1.60288 | G21: 1.60225 | H21: 4.4686194 | I21: -0.039304252
B22: Brócoli | C22: 2.985 | D22: 3.40325 | E22: 3.70775 | F22: 4.09 | G22: 4.154 | H22: 8.6126823 | I22: 1.5647922
B23: Lechuga | C23: 4.81486 | D23: 5.51531 | E23: 5.856719 | F23: 6.40033 | G23: 6.7411 | H23: 8.7769247 | I23: 5.3242567
B24: Espinaca | C24: 1.6137 | D24: 1.6526 | E24: 1.7095 | F24: 1.7152 | G24: 1.618 | H24: 0.066550627 | I24: -5.6669776
B25: Alcachofa | C25: 7.89347 | D25: 5.86025 | E25: 5.2903289 | F25: 5.51325 | G25: 6.0925 | H25: -6.2692928 | I25: 10.506507
B26: Acelga | C26: 0.7952 | D26: 0.7316 | E26: 0.606 | F26: 0.5845 | G26: 0.5275 | H26: -9.7522209 | I26: -9.7519247
B27: Culantro | C27: 1.65075 | D27: 1.697 | E27: 1.7622 | F27: 2.0791 | G27: 1.9517 | H27: 4.275658 | I27: -6.1276514
B28: Perejil | C28: 0.3988 | D28: 0.3531 | E28: 0.2775 | F28: 0.31968 | G28: 0.3125 | H28: -5.9142789 | I28: -2.245996
B29: Sandia | C29: 3.63395 | D29: 3.3914 | E29: 3.22954 | F29: 3.4047 | G29: 3.52997 | H29: -0.72314361 | I29: 3.6793256
B30: Melón | C30: 1.0677 | D30: 1.0355 | E30: 1.01455 | F30: 1.1154 | G30: 1.2369 | H30: 3.7459942 | I30: 10.892953
... B55: Apio | C55: 1.3582 | D55: 1.50295 | E55: 1.52295 | F55: 1.5445 | G55: 1.74375 | H55: 6.4461905 | I55: 12.900615
A56: Frutas y nueces | C56: 399.06296 | D56: 422.31389 | E56: 426.68313 | F56: 438.80935 | G56: 441.35027 | H56: 2.5499597 | I56: 0.57904828
B57: Palta | C57: 23.642 | D57: 25.75 | E57: 30.319729 | F57: 33.988829 | G57: 37.871179 | H57: 12.500941 | I57: 11.422429
B58: Banano y plátano | C58: 157.12 | D58: 164.995 | E58: 166.03832 | F58: 167.83912 | G58: 160.6462 | H58: 0.55640689 | I58: -4.285604
B59: Dátil | C59: 0.105 | D59: 0.105 | E59: 0.071 | F59: 0.071 | G59: 0.085 | H59: -5.1456163 | I59: 19.71831
B60: Higo | C60: 0.58125 | D60: 0.57175 | E60: 0.53975 | F60: 0.54075 | G60: 0.52425 | H60: -2.5473017 | I60: -3.0513176
B61: Mango | C61: 26.983 | D61: 31.741 | E61: 31.18341 | F61: 29.73338 | G61: 22.09199 | H61: -4.8768658 | I61: -25.699702
B62: Guayaba | C62: 0.940557 | D62: 0.984478 | E62: 1.01239 | F62: 0.98972 | G62: 0.98145 | H62: 1.0696507 | I62: -0.83558986
B63: Papaya | C63: 9.7 | D63: 12.025 | E63: 12.48797 | F63: 11.35008 | G63: 12.328449 | H63: 6.1779112 | I63: 8.6199304
B64: Piña | C64: 15.967 | D64: 15.629 | E64: 15.917338 | F64: 15.18196 | G64: 14.8831 | H64: -1.7420908 | I64: -1.9685205
B65: Maracuyá | C65: 4.600139 | D65: 4.38786 | E65: 4.13424 | F65: 4.59954 | G65: 4.99424 | H65: 2.076228 | I65: 8.5812929
...

Sheet C.6
A1: C.6 PERÚ: PRODUCCIÓN AGRÍCOLA POR PRODUCTO SEGÚN AÑO, 2012-2016
A2: (Miles toneladas)
A4: Producto | C4: 2012 | D4: 2013 | E4: 2014 | F4: 2015 | G4: 2016 | H4: % 2012-2016 | I4: % 2016/ 2015
A5: Cereales
B6: Trigo | C6: 226.21846 | D6: 230.11206 | E6: 218.90376 | F6: 214.84862 | G6: 191.10827 | H6: -4.1288665 | I6: -11.0498 | K6: Marigold | L6: -0.72998326
B7: Maíz amarillo duro | C7: 1392.9717 | D7: 1364.6633 | E7: 1227.5619 | F7: 1438.5624 | G7: 1232.383 | H7: -3.0158308 | I7: -14.332326 | K7: Garbanzo | L7: -0.35207337
B8: Maíz amiláceo | C8: 280.90195 | D8: 307.48076 | E8: 302.07438 | F8: 307.86517 | G8: 277.42609 | H8: -0.3107936 | I8: -9.887145 | K8: Piquillo | L8: -0.20752685
B9: Maíz morado | C9: 18.506417 | D9: 20.117286 | E9: 17.960068 | F9: 21.160248 | G9: 21.356781 | H9: 3.6461949 | I9: 0.92878401 | K9: Algodón | L9: -0.20039032
B10: Arroz con cascarilla | C10: 3043.3305 | D10: 3046.7727 | E10: 2896.6127 | F10: 3151.4084 | G10: 3165.749 | H10: 0.99080666 | I10: 0.45505216 | K10: Sacha inchi | L10: -0.14964009
B11: Sorgo grano | C11: 0.125 | D11: 0.149 | E11: 0.418 | F11: 0.157109 | G11: 0.16756 | H11: 7.600697 | I11: 6.6520696 | K11: Zapote | L11: -0.14595538
B12: Cebada grano | C12: 214.48874 | D12: 224.53309 | E12: 226.31003 | F12: 227.16845 | G12: 204.4972 | H12: -1.1854917 | I12: -9.9799302 | K12: Perejil | L12: -0.13077512
B13: Avena grano | C13: 13.401337 | D13: 13.28715 | E13: 14.672108 | F13: 15.908088 | G13: 20.845869 | H13: 11.678088 | I13: 31.039437 | K13: Olivo | L13: -0.11736161
B14: Quinua | C14: 44.2126 | D14: 52.129766 | E14: 114.72468 | F14: 105.66575 | G14: 79.268806 | H14: 15.714842 | I14: -24.981548 | K14: Soya | L14: -0.11657105
B15: Kiwicha | C15: 2.751808 | D15: 2.506499 | E15: 2.356449 | F15: 4.848368 | G15: 2.724929 | H15: -0.24509359 | I15: -43.796985 | K15: Lenteja | L15: -0.11292721
B16: Cañihua | C16: 4.940379 | D16: 4.64425 | E16: 4.86794 | F16: 4.733859 | G16: 4.56503 | H16: -1.9560404 | I16: -3.5664138 | K16: Caupí | L16: -0.10211609
A17: Hortalizas | K17: Acelga | L17: -0.10005709
B18: Espárrago | C18: 375.97771 | D18: 383.14373 | E18: 377.70097 | F18: 369.03205 | G18: 378.30579 | H18: 0.1544437 | I18: 2.5129901 | K18: Paprika | L18: -0.097413703
B19: Col | C19: 40.045495 | D19: 39.773444 | E19: 39.264908 | F19: 39.563524 | G19: 37.794905 | H19: -1.4356419 | I19: -4.4703273 | K19: Brocoli | L19: 0.10281667
B20: Coliflor | C20: 18.353264 | D20: 21.097008 | E20: 17.546929 | F20: 19.517261 | G20: 19.23021 | H20: 1.1737107 | I20: -1.4707545 | K20: Copoazu | L20: 0.11285385
B21: Brocoli | C21: 37.29866 | D21: 43.38335 | E21: 48.800535 | F21: 54.52703 | G21: 55.170448 | H21: 10.281667 | I21: 1.1799983 | K21: Avena grano | L21: 0.11678088
B22: Lechuga | C22: 53.130168 | D22: 59.925284 | E22: 64.320246 | F22: 68.624245 | G22: 73.559433 | H22: 8.4736605 | I22: 7.1916099 | K22: Chirimoya | L22: 0.11794475
B23: Espinaca | C23: 29.373122 | D23: 29.77574 | E23: 29.883187 | F23: 30.018087 | G23: 28.534803 | H23: -0.7212747 | I23: -4.9413009 | K23: Granadilla | L23: 0.13336151
B24: Alcachofa | C24: 141.7075 | D24: 112.93257 | E24: 103.34811 | F24: 89.98298 | G24: 108.80133 | H24: -6.3925657 | I24: 20.913233 | K24: Palta | L24: 0.14117061
B25: Acelga | C25: 11.404759 | D25: 10.625787 | E25: 8.973752 | F25: 8.393938 | G25: 7.480764 | H25: -10.005709 | I25: -10.87897 | K25: Cacao | L25: 0.1463616
B26: Culantro | C26: 22.215649 | D26: 21.560002 | E26: 22.320741 | F26: 23.64906 | G26: 21.958812 | H26: -0.29028869 | I26: -7.1472101 | K26: Quinua | L26: 0.15714842
B27: Perejil | C27: 7.93944 | D27: 4.555719 | E27: 4.681608 | F27: 5.0733 | G27: 4.532298 | H27: -13.077512 | I27: -10.66371 | K27: Uva | L27: 0.17508004
B28: Sandia | C28: 94.93389 | D28: 91.216984 | E28: 91.370234 | F28: 95.797327 | G28: 85.679719 | H28: -2.5315209 | I28: -10.561472 | K28: Rocoto | L28: 0.18781867
B29: Melón | C29: 21.052825 | D29: 20.578497 | E29: 21.115785 | F29: 22.340887 | G29: 21.148228 | H29: 0.11309801 | I29: -5.3384586 | K29: Mango | L29: 0.19173183
... B35: Berenjena | C35: 0.4159 | D35: 0.2751 | E35: 0.3216 | F35: 0.43115 | G35: 0.361 | H35: -3.4772759 | I35: -16.27044 | K35: Arándano | L35: 2.8104195
B36: Tomate | C36: 229.35647 | D36: 253.58841 | E36: 265.94804 | F36: 236.28717 | G36: 232.89789 | H36: 0.38380148 | I36: -1.4343931
B37: Calabaza | C37: 11.709299 | D37: 13.400627 | E37: 13.07148 | F37: 13.48074 | G37: 13.59533 | H37: 3.8041495 | I37: 0.85002752
B38: Zapallo macre | C38: 209.89753 | D38: 219.48711 | E38: 237.20437 | F38: 239.59402 | G38: 206.88766 | H38: -0.3604373 | I38: -13.650741
B39: Caigua | C39: 6.315017 | D39: 6.70723 | E39: 6.032186 | F39: 8.112705 | G39: 7.245786 | H39: 3.4969961 | I39: -10.685943
B40: Vainita | C40: 17.133389 | D40: 18.85365 | E40: 16.840275 | F40: 22.702565 | G40: 19.908544 | H40: 3.8243106 | I40: -12.307072
B41: Frijol verde | C41: 12.035612 | D41: 14.954386 | E41: 14.996228 | F41: 15.831896 | G41: 14.734398 | H41: 5.1879653 | I41: -6.9321956
B42: Pallar verde | C42: 4.74226 | D42: 5.497039 | E42: 5.15733 | F42: 6.16453 | G42: 5.33299 | H42: 2.9784503 | I42: -13.489106
B43: Arveja verde | C43: 117.37716 | D43: 130.06515 | E43: 133.65849 | F43: 135.33515 | G43: 120.12533 | H43: 0.58025805 | I43: -11.238637
B44: Haba verde | C44: 65.447915 | D44: 68.621206 | E44: 68.327258 | F44: 71.242818 | G44: 64.340522 | H44: -0.42571626 | I44: -9.6884096
B45: Zanahoria | C45: 179.7282 | D45: 178.20719 | E45: 173.32939 | F45: 176.22026 | G45: 172.24431 | H45: -1.0576634 | I45: -2.2562417
B46: Nabo | C46: 11.542833 | D46: 11.046215 | E46: 11.692997 | F46: 9.50509 | G46: 8.814378 | H46: -6.5197609 | I46: -7.2667592
...

Sheet C.7
A1: C.7 PERÚ: RENDIMIENTO AGRÍCOLA POR PRODUCTO SEGÚN AÑO, 2012-2016
A2: (Toneladas por hectárea)
K3: Olivo | L3: -0.1715214
A4: Producto | C4: 2012 | D4: 2013 | E4: 2014 | F4: 2015 | G4: 2016 | H4: % 2012-2016 | I4: % 2016/ 2015 | K4: Taperibá | L4: -0.14198979
A5: Cereales | K5: Aguaymanto | L5: -0.079733113
B6: Trigo | C6: 1.4887459 | D6: 1.4976706 | E6: 1.5554157 | F6: 1.5528554 | G6: 1.5026628 | H6: 0.23288696 | I6: -3.2322802 | K6: Perejil | L6: -0.076135183
B7: Maíz amarillo duro | C7: 4.7244491 | D7: 4.6461644 | E7: 4.5283302 | F7: 4.8340713 | G7: 4.6057392 | H7: -0.63417508 | I7: -4.7233913 | K7: Sacha inchi | L7: -0.075616642
B8: Maíz amiláceo | C8: 1.3422733 | D8: 1.4180577 | E8: 1.4184446 | F8: 1.4236832 | G8: 1.4060309 | H8: 1.1669083 | I8: -1.2399034 | K8: Copoazu | L8: -0.066793173
B9: Maíz morado | C9: 4.9546517 | D9: 5.6773963 | E9: 5.642497 | F9: 5.6098218 | G9: 5.5005682 | H9: 2.6475539 | I9: -1.9475427 | K9: Loctao | L9: -0.055444742
B10: Arroz con cascarilla | C10: 7.7263404 | D10: 7.7127574 | E10: 7.5953234 | F10: 7.8883618 | G10: 7.5453438 | H10: -0.5908639 | I10: -4.3484057 | K10: Pan de árbol | L10: -0.053609134
B11: Sorgo grano | C11: 3.5714286 | D11: 3.8205128 | E11: 4.4 | F11: 4.0284359 | G11: 3.8081818 | H11: 1.6175984 | I11: -5.4674838 | K11: Damasco | L11: -0.050929294
B12: Cebada grano | C12: 1.4184497 | D12: 1.4568097 | E12: 1.5004685 | F12: 1.5576884 | G12: 1.506493 | H12: 1.5168868 | I12: -3.286632 | K12: Guinda | L12: 0.05172811
B13: Avena grano | C13: 1.1983937 | D13: 1.1713448 | E13: 1.1792403 | F13: 1.2238874 | G13: 1.3199269 | H13: 2.4442504 | I13: 7.8470865 | K13: Orégano | L13: 0.054478253
B14: Quinua | C14: 1.1484338 | D14: 1.1618507 | E14: 1.6836526 | F14: 1.5246933 | G14: 1.2342708 | H14: 1.8183649 | I14: -19.047934 | K14: Cacao | L14: 0.059115444
B15: Kiwicha | C15: 1.6017509 | D15: 1.5349045 | E15: 1.7336391 | F15: 2.1176536 | G15: 1.7032935 | H15: 1.548528 | I15: -19.566944 | K15: Chirimoya | L15: 0.059156916
B16: Cañihua | C16: 0.77253776 | D16: 0.74000159 | E16: 0.76132937 | F16: 0.77035948 | G16: 0.74167831 | H16: -1.0139566 | I16: -3.723089 | K16: Ciruela roja | L16: 0.05934749
A17: Hortalizas | K17: Tamarindo | L17: 0.069470419
B18: Espárrago | C18: 11.371554 | D18: 11.378366 | E18: 11.833052 | F18: 10.895688 | G18: 11.83426 | H18: 1.0020799 | I18: 8.6141598 | K18: Pepino | L18: 0.070958769
B19: Col | C19: 13.844692 | D19: 14.191117 | E19: 14.325898 | F19: 14.567103 | G19: 14.844118 | H19: 1.7578148 | I19: 1.9016443 | K19: Uva | L19: 0.087970716
B20: Coliflor | C20: 13.643521 | D20: 13.326727 | E20: 12.940213 | F20: 12.176371 | G20: 12.002003 | H20: -3.1539698 | I20: -1.4320131 | K20: Tangelo | L20: 0.089066135
B21: Brocoli | C21: 12.495363 | D21: 12.747624 | E21: 13.161765 | F21: 13.331792 | G21: 13.281283 | H21: 1.5366384 | I21: -0.37886547 | K21: Berenjena | L21: 0.10215278
B22: Lechuga | C22: 11.034624 | D22: 10.865261 | E22: 10.9823 | F22: 10.721985 | G22: 10.912082 | H22: -0.2787946 | I22: 1.7729564 | K22: Dátil | L22: 0.12527526
B23: Espinaca | C23: 18.202344 | D23: 18.017512 | E23: 17.480659 | F23: 17.501217 | G23: 17.635849 | H23: -0.78730137 | I23: 0.76927115 | K23: Granada | L23: 0.13985139
B24: Alcachofa | C24: 17.952497 | D24: 19.270947 | E24: 19.53529 | F24: 16.321223 | G24: 17.85824 | H24: -0.1315181 | I24: 9.4172967 | K24: Frijol de palo | L24: 0.15770786
B25: Acelga | C25: 14.342001 | D25: 14.524039 | E25: 14.808172 | F25: 14.360886 | G25: 14.181543 | H25: -0.28088001 | I25: -1.2488303 | K25: Mango | L25: 0.25283071
B26: Culantro | C26: 13.457912 | D26: 12.704774 | E26: 12.666406 | F26: 11.374662 | G26: 11.251121 | H26: -4.3787273 | I26: -1.0861118 | K26: Arándano | L26: 0.56970417
B27: Perejil | C27: 19.908325 | D27: 12.902065 | E27: 16.870659 | F27: 15.869932 | G27: 14.503354 | H27: -7.6135183 | I27: -8.6111194 | K27: Pacae y guaba | L27: 0.65359434
B28: Sandia | C28: 26.12416 | D28: 26.896557 | E28: 28.292027 | F28: 28.136789 | G28: 24.272081 | H28: -1.8215498 | I28: -13.735427
B29: Melón | C29: 19.717922 | D29: 19.873005 | E29: 20.812956 | F29: 20.029484 | G29: 17.097767 | H29: -3.5017218 | I29: -14.637009
B30: Ají | C30: 10.297459 | D30: 9.8784219 | E30: 10.084331 | F30: 10.297966 | G30: 9.4407193 | H30: -2.148216 | I30: -8.3244257
B31: Rocoto | C31: 10.774661 | D31: 10.140075 | E31: 8.2281798 | F31: 10.204123 | G31: 12.35785 | H31: 3.4867696 | I31: 21.106442
B32: Piquillo | C32: 22.832829 | D32: 23.871353 | E32: 27.388889 | F32: 26.257928 | G32: 25.54721 | H32: 2.848021 | I32: -2.706679
B33: Pimiento morrón | C33: 23.869482 | D33: 20.835018 | E33: 26.688749 | F33: 26.875265 | G33: 25.77484 | H33: 1.9385022 | I33: -4.094562
B34: Pepinillo | C34: 16.242855 | D34: 16.242858 | E34: 16.962412 | F34: 16.852741 | G34: 17.944891 | H34: 2.5226012 | I34: 6.4805489
B35: Berenjena | C35: 8.154902 | D35: 12.226667 | E35: 13.4 | F35: 11.652703 | G35: 12.033333 | H35: 10.215278 | I35: 3.2664579
B36: Tomate | C36: 41.097057 | D36: 43.897351 | E36: 44.293669 | F36: 40.020795 | G36: 38.367732 | H36: -1.7033198 | I36: -4.1305099
B37: Calabaza | C37: 10.47766 | D37: 10.106054 | E37: 9.9478539 | F37: 10.518516 | G37: 10.894139 | H37: 0.97925184 | I37: 3.5710692
B38: Zapallo macre | C38: 28.325297 | D38: 28.000806 | E38: 30.362742 | F38: 28.100915 | G38: 26.637096 | H38: -1.5245216 | I38: -5.2091501
B39: Caigua | C39: 4.9241818 | D39: 4.3610078 | E39: 4.3798773 | F39: 5.1330965 | G39: 4.8048979 | H39: -0.61118333 | I39: -6.3937743
... B54: Apio | C54: 18.494786 | D54: 18.155925 | E54: 18.52638 | F54: 18.52325 | G54: 17.945088 | H54: -0.75147189 | I54: -3.1212727
...

Sheet C.8
A1: C.8 PERÚ: PRECIO RECIBIDO POR EL PRODUCTOR POR PRODUCTO SEGÚN AÑO, 2011-2015
A2: (Soles por tonelada)
A4: Producto | C4: 2012 | D4: 2013 | E4: 2014 | F4: 2015 | G4: 2016 | H4: % 2012-2016 | I4: % 2016/ 2015 | K4: Banano y plátano | L4: -0.25798976
A5: Cereales | K5: Cebolla cabeza | L5: -0.15074692
B6: Trigo | C6: 1316.8088 | D6: 1374.1632 | E6: 1448.5268 | F6: 1505.3321 | G6: 1567.3639 | H6: 4.4508014 | I6: 4.1208043 | K6: Arándano | L6: -0.13413489
B7: Maíz amarillo duro | C7: 833.16146 | D7: 878.58264 | E7: 904.446 | F7: 899.46034 | G7: 991.71405 | H7: 4.4514141 | I7: 10.256563 | K7: Mango | L7: -0.11412557
B8: Maíz amiláceo | C8: 2132.545 | D8: 2284.8583 | E8: 2282.2601 | F8: 2145.9504 | G8: 2337.8966 | H8: 2.3250053 | I8: 8.9445781 | K8: Maca | L8: -0.099777516
B9: Maíz morado | C9: 1221.4545 | D9: 1245.6902 | E9: 1260.562 | F9: 1230.9686 | G9: 1617.3182 | H9: 7.2703119 | I9: 31.385819 | K9: Papa | L9: 0.097147771
B10: Arroz con cascarilla | C10: 886.82869 | D10: 870.55838 | E10: 1092.5321 | F10: 1094.5678 | G10: 1152.0871 | H10: 6.7606952 | I10: 5.2549766 | K10: Pecana | L10: 0.098629522
B11: Sorgo grano | C11: 560 | D11: 660 | E11: 750 | F11: 579.90631 | G11: 597.77513 | H11: 1.6453354 | I11: 3.0813285 | K11: Dátil | L11: 0.10093173
B12: Cebada grano | C12: 1080.9382 | D12: 1164.4766 | E12: 1230.6127 | F12: 1222.497 | G12: 1240.0899 | H12: 3.4934993 | I12: 1.4390935 | K12: Espárrago | L12: 0.10648495
B13: Avena grano | C13: 1362.9822 | D13: 1487.5975 | E13: 1694.8453 | F13: 1498.7182 | G13: 1630.0985 | H13: 4.5757324 | I13: 8.7661749 | K13: Damasco | L13: 0.11331177
B14: Quinua | C14: 3880.8574 | D14: 6293.0113 | E14: 7875.2291 | F14: 4906.2421 | G14: 3985.7505 | H14: 0.66896572 | I14: -18.761642 | K14: Caimito | L14: 0.11363454
B15: Kiwicha | C15: 3591.0952 | D15: 3663.6948 | E15: 6644.1471 | F15: 4312.4094 | G15: 3483.7484 | H15: -0.75583869 | I15: -19.215731 | K15: Pituca | L15: 0.11800773
B16: Cañihua | C16: 3081.7121 | D16: 3991.1287 | E16: 4973.8854 | F16: 5237.6446 | G16: 4136.1413 | H16: 7.634333 | I16: -21.030508 | K16: Marigold | L16: 0.12241239
A17: Hortalizas | K17: Alcachofa | L17: 0.12425019
B18: Espárrago | C18: 2798.462 | D18: 3053.2669 | E18: 2652.2224 | F18: 3764.4445 | G18: 4194.7054 | H18: 10.648495 | I18: 11.429598 | K18: Cacao | L18: 0.13385483
B19: Col | C19: 653.34265 | D19: 672.02341 | E19: 711.9152 | F19: 741.02609 | G19: 772.64716 | H19: 4.2821678 | I19: 4.2672006 | K19: Anona | L19: 0.13940947
B20: Coliflor | C20: 746.08239 | D20: 779.62258 | E20: 830.9271 | F20: 840.48941 | G20: 1011.3029 | H20: 7.9005407 | I20: 20.323104 | K20: Higo | L20: 0.14585543
B21: Brocoli | C21: 804.63322 | D21: 927.87486 | E21: 1022.6616 | F21: 1034.7867 | G21: 1120.6223 | H21: 8.6338885 | I21: 8.295 | K21: Fresa | L21: 0.14961439
B22: Lechuga | C22: 635.81183 | D22: 753.00848 | E22: 800.03608 | F22: 735.32166 | G22: 834.00337 | H22: 7.018732 | I22: 13.42021 | K22: Guayaba | L22: 0.15191253
B23: Espinaca | C23: 741.14549 | D23: 832.38698 | E23: 893.54803 | F23: 934.67959 | G23: 1012.2615 | H23: 8.10538 | I23: 8.3003706 | K23: Zapote | L23: 0.17292942
B24: Alcachofa | C24: 1416.767 | D24: 1586.3512 | E24: 2172.2293 | F24: 1658.0133 | G24: 2263.3426 | H24: 12.425019 | I24: 36.509316 | K24: Olivo | L24: 0.17421003
B25: Acelga | C25: 736.76103 | D25: 825.77703 | E25: 861.04211 | F25: 907.8417 | G25: 992.71442 | H25: 7.7393673 | I25: 9.3488459 | K25: Marañón | L25: 0.17482185
B26: Culantro | C26: 522.09366 | D26: 613.53447 | E26: 617.71359 | F26: 671.25125 | G26: 683.3586 | H26: 6.9609031 | I26: 1.8036987 | K26: Rye grass | L26: 0.1953638
B27: Perejil | C27: 558.93451 | D27: 582.45859 | E27: 595.46763 | F27: 618.90876 | G27: 693.84976 | H27: 5.5543486 | I27: 12.108571 | K27: Guanábana | L27: 0.19778792
B28: Sandia | C28: 561.82226 | D28: 541.43869 | E28: 728.08249 | F28: 646.64631 | G28: 610.40563 | H28: 2.0950995 | I28: -5.6044054 | K28: Ajo | L28: 0.22044115
B29: Melón | C29: 682.48722 | D29: 730.89281 | E29: 682.83089 | F29: 682.83089 | G29: 712.67122 | H29: 1.0877836 | I29: 4.3700911 | K29: Granada | L29: 0.22956634
... B32: Piquillo | C32: 1034.3999 | D32: 830.11112 | E32: 1338.1039 | F32: 971.93076 | G32: 911.62117 | H32: -3.1094355 | I32: -6.2051323 | K32: Pan de árbol | L32: 0.33021627
B33: Pimiento morrón | C33: 1018.3634 | D33: 1169.528 | E33: 1093.3234 | F33: 881.10614 | G33: 909.50212 | H33: -2.786801 | I33: 3.2227653
B34: Pepinillo | C34: 426.92059 | D34: 415.20062 | E34: 450.71117 | F34: 414.83842 | G34: 410.24671 | H34: -0.99103941 | I34: -1.1068663
B35: Berenjena | C35: 913.18827 | D35: 980.84333 | E35: 1157.8358 | F35: 1216.7343 | G35: 1232.7424 | H35: 7.7898832 | I35: 1.3156584
B36: Tomate | C36: 766.20789 | D36: 712.31285 | E36: 997.28549 | F36: 848.02888 | G36: 907.61784 | H36: 4.32517 | I36: 7.0267611
B37: Calabaza | C37: 467.14717 | D37: 446.94406 | E37: 525.0539 | F37: 555.40968 | G37: 632.06756 | H37: 7.8518115 | I37: 13.802042
B38: Zapallo macre | C38: 536.20191 | D38: 516.94977 | E38: 711.30664 | F38: 701.26614 | G38: 655.9156 | H38: 5.1671006 | I38: -6.4669517
B39: Caigua | C39: 817.74367 | D39: 811.22387 | E39: 839.07695 | F39: 728.45997 | G39: 780.83081 | H39: -1.148119 | I39: 7.1892545
B40: Vainita | C40: 1372.0972 | D40: 1425.1947 | E40: 1516.4639 | F40: 1329.7184 | G40: 1490.321 | H40: 2.087774 | I40: 12.077934
B41: Frijol verde | C41: 1128.4695 | D41: 1222.9381 | E41: 1140.3518 | F41: 1306.8047 | G41: 1456.3724 | H41: 6.584892 | I41: 11.445294
B42: Pallar verde | C42: 1315.4009 | D42: 1357.0237 | E42: 1215.976 | F42: 1156.3219 | G42: 1228.2078 | H42: -1.7000195 | I42: 6.2167743
B43: Arveja verde | C43: 1335.6589 | D43: 1475.3637 | E43: 1548.1959 | F43: 1562.2019 | G43: 1609.7369 | H43: 4.7767295 | I43: 3.0428181
...

Sheet C.9
A1: C.9 PERÚ: SUPERFICIE SEMBRADA DE CEREALES POR REGIÓN SEGÚN CULTIVO, AGO 2015-JUL 2016
A2: (Hectáreas)
A4: Región | B4: TOTAL | C4: Trigo | D4: Maíz amarillo duro | E4: Maíz amiláceo1 | F4: Maíz morado | G4: Arroz | H4: Sorgo grano | I4: Cebada grano | J4: Avena grano | K4: Quinua | L4: Kiwicha | M4: Cañihua
A5: Nacional | B5: =+SUM(C5:M5) -> 1303313.8 | C5: 127491.75 | D5: 277566.64 | E5: 249443.8 | F5: 3965.65 | G5: 417084.25 | H5: 44 | I5: 137479.25 | J5: 15791.5 | K5: 66625.75 | L5: 1691.25 | M5: 6130
A6: Amazonas | B6: =+SUM(C6:M6) -> 63021 | C6: 466 | D6: 12033.8 | E6: 8391.7 | F6: 0 | G6: 41931.5 | H6: 0 | I6: 137 | J6: 0 | K6: 61 | L6: 0 | M6: 0
A7: Ancash | B7: =+SUM(C7:M7) -> 57816 | C7: 12275 | D7: 16443 | E7: 13713 | F7: 576 | G7: 6795 | H7: 0 | I7: 7336 | J7: 0 | K7: 344 | L7: 334 | M7: 0
A8: Apurímac | B8: =+SUM(C8:M8) -> 44590 | C8: 4959.5 | D8: 2291.5 | E8: 27072 | F8: 92 | G8: 0 | H8: 0 | I8: 4499.75 | J8: 720.5 | K8: 4250 | L8: 704.75 | M8: 0
A9: Arequipa | B9: =+SUM(C9:M9) -> 29254 | C9: 1641 | D9: 197 | E9: 4593 | F9: 385 | G9: 19954 | H9: 39 | I9: 409 | J9: 0 | K9: 1943 | L9: 83 | M9: 10
A10: Ayacucho | B10: =+SUM(C10:M10) -> 59862 | C10: 9244 | D10: 803 | E10: 21093 | F10: 513 | G10: 80 | H10: 0 | I10: 13365 | J10: 1772 | K10: 12897 | L10: 95 | M10: 0
A11: Cajamarca | B11: =+SUM(C11:M11) -> 132127.75 | C11: 27171 | D11: 18175 | E11: 50475.5 | F11: 248 | G11: 25222.5 | H11: 0 | I11: 9955.75 | J11: 0 | K11: 880 | L11: 0 | M11: 0
A12: Cusco | B12: =+SUM(C12:M12) -> 64257 | C12: 10232 | D12: 2322 | E12: 28149 | F12: 0 | G12: 1179 | H12: 0 | I12: 14462 | J12: 3809 | K12: 3133 | L12: 374 | M12: 597
A13: Huancavelica | B13: =+SUM(C13:M13) -> 39227.25 | C13: 4682.25 | D13: 242.5 | E13: 17888 | F13: 0 | G13: 0 | H13: 0 | I13: 14777 | J13: 458 | K13: 1163 | L13: 16.5 | M13: 0
A14: Huánuco | B14: =+SUM(C14:M14) -> 50568 | C14: 8026 | D14: 10704.5 | E14: 14620.25 | F14: 252.25 | G14: 9243 | H14: 0 | I14: 6059.25 | J14: 833 | K14: 829.75 | L14: 0 | M14: 0
A15: Ica | B15: =+SUM(C15:M15) -> 19439.94 | C15: 52 | D15: 17726.19 | E15: 1411.35 | F15: 164.4 | G15: 0 | H15: 0 | I15: 78 | J15: 0 | K15: 8 | L15: 0 | M15: 0
A16: Junín | B16: =+SUM(C16:M16) -> 38989 | C16: 5184 | D16: 5521 | E16: 14486 | F16: 0 | G16: 1230 | H16: 0 | I16: 10556 | J16: 0 | K16: 2012 | L16: 0 | M16: 0
... A30: Ucayali | B30: =+SUM(C30:M30) -> 21903 | C30: 0 | D30: 12070 | E30: 0 | F30: 0 | G30: 9833 | H30: 0 | I30: 0 | J30: 0 | K30: 0 | L30: 0 | M30: 0
A31: 1 Incluye maíz choclo
A32: Fuente: SIEA

Sheet C.10
A1: C.10 PERÚ: SUPERFICIE COSECHADA DE CEREALES POR REGIÓN SEGÚN CULTIVO, AÑO 2016
A2: (Hectáreas)
A4: Región | B4: TOTAL | C4: Trigo | D4: Maíz amarillo duro | E4: Maíz amiláceo | F4: Maíz morado | G4: Arroz | H4: Sorgo grano | I4: Cebada grano | J4: Avena grano | K4: Quinua | L4: Kiwicha | M4: Cañihua | O4: Arroz | P4: 419.56325
A5: Nacional | B5: =+SUM(C5:M5) -> 1239071.7 | C5: 127179.75 | D5: 267575.5 | E5: 197311.52 | F5: 3882.65 | G5: 419563.25 | H5: 44 | I5: 135743.88 | J5: 15793.2 | K5: 64223.19 | L5: 1599.8 | M5: 6155 | O5: Maíz amarillo duro | P5: 267.5755
A6: Amazonas | B6: =+SUM(C6:M6) -> 61921.3 | C6: 474 | D6: 12171.3 | E6: 7511 | F6: 0 | G6: 41567 | H6: 0 | I6: 137 | J6: 0 | K6: 61 | L6: 0 | M6: 0 | O6: Maíz amiláceo | P6: 197.31152
A7: Ancash | B7: =+SUM(C7:M7) -> 53007 | C7: 12262 | D7: 16440 | E7: 8932 | F7: 581 | G7: 6795 | H7: 0 | I7: 7325 | J7: 0 | K7: 352 | L7: 320 | M7: 0 | O7: Cebada grano | P7: 135.74388
A8: Apurímac | B8: =+SUM(C8:M8) -> 38873 | C8: 4760.5 | D8: 2156.5 | E8: 22035 | F8: 49 | G8: 0 | H8: 0 | I8: 4348.75 | J8: 720.5 | K8: 4100 | L8: 702.75 | M8: 0 | O8: Trigo | P8: 127.17975
A9: Arequipa | B9: =+SUM(C9:M9) -> 26859 | C9: 1638 | D9: 194 | E9: 2346 | F9: 385 | G9: 19939 | H9: 39 | I9: 394 | J9: 0 | K9: 1831 | L9: 83 | M9: 10 | O9: Quinua | P9: 64.22319
A10: Ayacucho | B10: =+SUM(C10:M10) -> 52935 | C10: 8655 | D10: 863 | E10: 17013 | F10: 464 | G10: 80 | H10: 0 | I10: 12476 | J10: 1772 | K10: 11515 | L10: 97 | M10: 0 | O10: Avena grano | P10: 15.7932
A11: Cajamarca | B11: =+SUM(C11:M11) -> 121013.75 | C11: 28344 | D11: 18507 | E11: 37673 | F11: 248 | G11: 24886 | H11: 0 | I11: 10477.75 | J11: 0 | K11: 878 | L11: 0 | M11: 0 | O11: Cañihua | P11: 6.155
A12: Cusco | B12: =+SUM(C12:M12) -> 61558.59 | C12: 10338.25 | D12: 2866 | E12: 24588.77 | F12: 0 | G12: 1476 | H12: 0 | I12: 14455.13 | J12: 3829.2 | K12: 3087.69 | L12: 295.55 | M12: 622 | O12: Maíz morado | P12: 3.88265
A13: Huancavelica | B13: =+SUM(C13:M13) -> 36295 | C13: 4317.75 | D13: 268.3 | E13: 16176.2 | F13: 0 | G13: 0 | H13: 0 | I13: 13863 | J13: 439.5 | K13: 1212.75 | L13: 17.5 | M13: 0 | O13: Kiwicha | P13: 1.5998
A14: Huánuco | B14: =+SUM(C14:M14) -> 49318.5 | C14: 7746.25 | D14: 10863.5 | E14: 13596 | F14: 252.25 | G14: 9151 | H14: 0 | I14: 6042.75 | J14: 833 | K14: 833.75 | L14: 0 | M14: 0 | O14: Sorgo grano | P14: 0.044
A15: Ica | B15: =+SUM(C15:M15) -> 18108.25 | C15: 52 | D15: 17741.3 | E15: 72.05 | F15: 156.9 | G15: 0 | H15: 0 | I15: 78 | J15: 0 | K15: 8 | L15: 0 | M15: 0
A16: Junín | B16: =+SUM(C16:M16) -> 32328.5 | C16: 5164 | D16: 5588 | E16: 7825.5 | F16: 0 | G16: 1214 | H16: 0 | I16: 10529 | J16: 0 | K16: 2008 | L16: 0 | M16: 0
A17: La Libertad | B17: =+SUM(C17:M17) -> 124902.2 | C17: 28704 | D17: 19083.2 | E17: 14486 | F17: 281.5 | G17: 32857 | H17: 5 | I17: 27358.5 | J17: 0 | K17: 2044 | L17: 83 | M17: 0
A18: Lambayeque | B18: =+SUM(C18:M18) -> 70481 | C18: 1473 | D18: 16532 | E18: 2616 | F18: 0 | G18: 49831 | H18: 0 | I18: 25 | J18: 0 | K18: 3 | L18: 1 | M18: 0
A19: Lima | B19: =+SUM(C19:M19) -> 23716 | C19: 143 | D19: 21567 | E19: 477 | F19: 1429 | G19: 0 | H19: 0 | I19: 92 | J19: 0 | K19: 8 | L19: 0 | M19: 0
A20: Lima Metropolitana | B20: =+SUM(C20:M20) -> 75 | C20: 2 | D20: 59 | E20: 0 | F20: 6 | G20: 0 | H20: 0 | I20: 1 | J20: 0 | K20: 7 | L20: 0 | M20: 0
A21: Loreto | B21: =+SUM(C21:M21) -> 69492 | C21: 0 | D21: 36446 | E21: 0 | F21: 0 | G21: 33046 | H21: 0 | I21: 0 | J21: 0 | K21: 0 | L21: 0 | M21: 0
A22: Madre de Dios | B22: =+SUM(C22:M22) -> 6693.5 | C22: 0 | D22: 4135 | E22: 0 | F22: 0 | G22: 2558.5 | H22: 0 | I22: 0 | J22: 0 | K22: 0 | L22: 0 | M22: 0
A23: Moquegua | B23: =+SUM(C23:M23) -> 960 | C23: 66 | D23: 51 | E23: 640 | F23: 30 | G23: 0 | H23: 0 | I23: 106 | J23: 0 | K23: 67 | L23: 0 | M23: 0
A24: Pasco | B24: =+SUM(C24:M24) -> 8606 | C24: 202 | D24: 3911 | E24: 1573 | F24: 0 | G24: 2777 | H24: 0 | I24: 138 | J24: 0 | K24: 5 | L24: 0 | M24: 0
A25: Piura | B25: =+SUM(C25:M25) -> 111063 | C25: 11318 | D25: 16608 | E25: 15447 | F25: 0 | G25: 67373 | H25: 0 | I25: 317 | J25: 0 | K25: 0 | L25: 0 | M25: 0
A26: Puno | B26: =+SUM(C26:M26) -> 85039 | C26: 1501 | D26: 2435 | E26: 3824 | F26: 0 | G26: 283 | H26: 0 | I26: 27580 | J26: 8199 | K26: 35694 | L26: 0 | M26: 5523
... A30: Ucayali | B30: =+SUM(C30:M30) -> 21250 | C30: 0 | D30: 11429 | E30: 0 | F30: 0 | G30: 9821 | H30: 0 | I30: 0 | J30: 0 | K30: 0 | L30: 0 | M30: 0
A31: Fuente: SIEA

Sheet C.11
A1: C.11 PERÚ: PRODUCCION DE CEREALES POR REGIÓN SEGÚN PRODUCTO, AÑO 2016
A2: (Toneladas)
A4: Región | B4: Trigo | C4: Maíz amarillo duro | D4: Maíz amiláceo | E4: Maíz morado | F4: Arroz cáscara | G4: Sorgo grano | H4: Cebada grano | I4: Avena grano | J4: Quinua | K4: Kiwicha | L4: Cañihua
A5: Nacional | B5: 191108.27 | C5: 1232383 | D5: 277426.09 | E5: 21356.781 | F5: 3165749 | G5: 167.56 | H5: 204497.2 | I5: 20845.869 | J5: 79268.806 | K5: 2724.929 | L5: 4565.03
A6: Amazonas | B6: 476.09 | C6: 27938.43 | D6: 6567.53 | E6: 0 | F6: 307947.11 | G6: 0 | H6: 127.63 | I6: 0 | J6: 62.88 | K6: 0 | L6: 0
A7: Ancash | B7: 11981.5 | C7: 107604.8 | D7: 10546.35 | E7: 3017.8 | F7: 65150 | G7: 0 | H7: 7152.2 | I7: 0 | J7: 401.6 | K7: 578.7 | L7: 0
A8: Apurímac | B8: 7338.26 | C8: 3963.3 | D8: 36873.039 | E8: 164 | F8: 0 | G8: 0 | H8: 7287.837 | I8: 1383.26 | J8: 6394.488 | K8: 1127.879 | L8: 0
A9: Arequipa | B9: 11388.23 | C9: 1367.223 | D9: 7263.042 | E9: 1964.042 | F9: 250051.44 | G9: 149.56 | H9: 1101.704 | I9: 0 | J9: 6206.238 | K9: 291.55 | L9: 8.52
A10: Ayacucho | B10: 9749 | C10: 1919 | D10: 18188 | E10: 1398 | F10: 201 | G10: 0 | H10: 13520 | I10: 2084 | J10: 16657 | K10: 100 | L10: 0
A11: Cajamarca | B11: 27696.768 | C11: 61636.368 | D11: 28383.628 | E11: 969.07 | F11: 195640.99 | G11: 0 | H11: 9784.749 | I11: 0 | J11: 750.76 | K11: 0 | L11: 0
A12: Cusco | B12: 17870.65 | C12: 4679.76 | D12: 60288.63 | E12: 0 | F12: 2597.5 | G12: 0 | H12: 26752.71 | I12: 7568.05 | J12: 3936.83 | K12: 496.4 | L12: 266.6
A13: Huancavelica | B13: 6614.187 | C13: 411.299 | D13: 25367.572 | E13: 0 | F13: 0 | G13: 0 | H13: 21256.208 | I13: 599.56 | J13: 1189.331 | K13: 19.2 | L13: 0
A14: Huánuco | B14: 8332 | C14: 43096 | D14: 12015 | E14: 1703 | F14: 48301 | G14: 0 | H14: 7943 | I14: 1261.5 | J14: 661 | K14: 0 | L14: 0
A15: Ica | B15: 87.69 | C15: 167414.18 | D15: 239.769 | E15: 812.489 | F15: 0 | G15: 0 | H15: 164.2 | I15: 0 | J15: 10.15 | K15: 0 | L15: 0
A16: Junín | B16: 11672.549 | C16: 17892.94 | D16: 17003.02 | E16: 0 | F16: 3958.9 | G16: 0 | H16: 22186.75 | I16: 0 | J16: 3801.71 | K16: 0 | L16: 0
... A30: Ucayali | B30: 0 | C30: 25790.26 | D30: 0 | E30: 0 | F30: 26934.345 | G30: 0 | H30: 0 | I30: 0 | J30: 0 | K30: 0 | L30: 0
A31: Fuente: SIEA

Sheet C.12
A1: C.12 PERU: TRIGO POR REGIÓN SEGÚN VARIABLES PRODUCTIVAS, 2015-2016
A3: Región | B3: Superficie cosechada (ha) | F3: Producción (t) | J3: Rendimiento (t/ ha) | M3: Precio al productor (S/ /t)
B4: 2015 | C4: 2016 | D4: Var. % | E4: Part % 2016 | F4: 2015 | G4: 2016 | H4: Var. % | I4: Part % 2016 | J4: 2015 | K4: 2016 | L4: Var. % | M4: 2015 | N4: 2016 | O4: Var. %
A5: Nacional | B5: 138357.13 | C5: 127179.75 | D5: -8.078644 | E5: 100 | F5: 214848.62 | G5: 191108.27 | H5: -11.0498 | I5: 100 | J5: 1.5528554 | K5: 1.5026628 | L5: -3.2322802 | M5: 1505.3321 | N5: 1567.3639 | O5: 4.1208043
A6: Amazonas | B6: 531 | C6: 474 | D6: -10.734463 | E6: 0.37270084 | F6: 572.1 | G6: 476.09 | H6: -16.782031 | I6: 0.24912056 | J6: 1.0774011 | K6: 1.0044093 | L6: -6.774807 | M6: 1688.4391 | N6: 1782.8486 | O6: 5.5915276
A7: Ancash | B7: 15707 | C7: 12262 | D7: -21.932896 | E7: 9.641472 | F7: 15874.2 | G7: 11981.5 | H7: -24.522181 | I7: 6.2694826 | J7: 1.0106449 | K7: 0.97712445 | L7: -3.3167421 | M7: 1959.3416 | N7: 1998.8315 | O7: 2.0154709
A8: Apurimac | B8: 4442 | C8: 4760.5 | D8: 7.1701936 | E8: 3.7431273 | F8: 7013.129 | G8: 7338.26 | H8: 4.6360334 | I8: 3.8398442 | J8: 1.5788224 | K8: 1.5414893 | L8: -2.3646129 | M8: 1397.3528 | N8: 1778.399 | O8: 27.269146
A9: Arequipa | B9: 2354 | C9: 1638 | D9: -30.416313 | E9: 1.2879409 | F9: 16284.314 | G9: 11388.23 | H9: -30.066259 | I9: 5.959046 | J9: 6.9177205 | K9: 6.9525214 | L9: 0.50306878 | M9: 1411.6197 | N9: 1418.9368 | O9: 0.51834447
